<sdf version='1.11'>
  <model name='PinkyPro'>
    <link name='base_footprint'>
      <inertial>
        <pose>-0.02637405595064924 0 0.05703618424104745 0 0 0</pose>
        <mass>1.03</mass>
        <inertia>
          <ixx>0.001522058050534081</ixx>
          <ixy>0</ixy>
          <ixz>-0.00020323060645294249</ixz>
          <iyy>0.001803494106882025</iyy>
          <iyz>0</iyz>
          <izz>0.001193071056347943</izz>
        </inertia>
      </inertial>
      <collision name='base_footprint_fixed_joint_lump__base_link_collision'>
        <pose>0 0 0.028000000000000001 0 0 0</pose>
        <geometry>
          <mesh>
            <scale>1 1 1</scale>
            <uri>model://PinkyPro/meshes/collision/base_link.stl</uri>
          </mesh>
        </geometry>
      </collision>
      <collision name='base_footprint_fixed_joint_lump__caster_mount_link_collision_1'>
        <pose>-0.058500000000000003 0 0.021000000000000001 0 0 0</pose>
        <geometry>
          <mesh>
            <scale>1 1 1</scale>
            <uri>model://PinkyPro/meshes/collision/caster_mount.stl</uri>
          </mesh>
        </geometry>
      </collision>
      <collision name='base_footprint_fixed_joint_lump__front_camera_mount_collision_2'>
        <pose>0.02 0 0.077499999999999999 0 0.13962634015954645 0</pose>
        <geometry>
          <mesh>
            <scale>1 1 1</scale>
            <uri>model://PinkyPro/meshes/collision/camera_assy.stl</uri>
          </mesh>
        </geometry>
      </collision>
      <collision name='base_footprint_fixed_joint_lump__rplidar_mount_collision_3'>
        <pose>-0.017000000000000001 0 0.095000000000000001 0 0 0</pose>
        <geometry>
          <mesh>
            <scale>1 1 1</scale>
            <uri>model://PinkyPro/meshes/collision/rplidar_c1.stl</uri>
          </mesh>
        </geometry>
      </collision>
      <collision name='base_footprint_fixed_joint_lump__screen_mount_collision_4'>
        <pose>0.016500000000000001 0 0.098999999999999991 0 -0.43633231299858238 0</pose>
        <geometry>
          <mesh>
            <scale>1 1 1</scale>
            <uri>model://PinkyPro/meshes/collision/screen_assy.stl</uri>
          </mesh>
        </geometry>
      </collision>
      <visual name='base_footprint_fixed_joint_lump__base_link_visual'>
        <pose>0 0 0.028000000000000001 0 0 0</pose>
        <geometry>
          <mesh>
            <scale>1 1 1</scale>
            <uri>model://PinkyPro/meshes/visual/base_link.dae</uri>
          </mesh>
        </geometry>
      </visual>
      <visual name='base_footprint_fixed_joint_lump__caster_mount_link_visual_1'>
        <pose>-0.058500000000000003 0 0.021000000000000001 0 0 0</pose>
        <geometry>
          <mesh>
            <scale>1 1 1</scale>
            <uri>model://PinkyPro/meshes/visual/caster_mount.dae</uri>
          </mesh>
        </geometry>
      </visual>
      <visual name='base_footprint_fixed_joint_lump__front_camera_mount_visual_2'>
        <pose>0.02 0 0.077499999999999999 0 0.13962634015954645 0</pose>
        <geometry>
          <mesh>
            <scale>1 1 1</scale>
            <uri>model://PinkyPro/meshes/visual/camera_assy.dae</uri>
          </mesh>
        </geometry>
      </visual>
      <visual name='base_footprint_fixed_joint_lump__rplidar_mount_visual_3'>
        <pose>-0.017000000000000001 0 0.095000000000000001 0 0 0</pose>
        <geometry>
          <mesh>
            <scale>1 1 1</scale>
            <uri>model://PinkyPro/meshes/visual/rplidar_c1.dae</uri>
          </mesh>
        </geometry>
      </visual>
      <visual name='base_footprint_fixed_joint_lump__screen_mount_visual_4'>
        <pose>0.016500000000000001 0 0.098999999999999991 0 -0.43633231299858238 0</pose>
        <geometry>
          <mesh>
            <scale>1 1 1</scale>
            <uri>model://PinkyPro/meshes/visual/screen_assy.dae</uri>
          </mesh>
        </geometry>
      </visual>
      <sensor name='camera' type='camera'>
        <camera>
          <horizontal_fov>1.1518999999999999</horizontal_fov>
          <image>
            <width>1280</width>
            <height>720</height>
          </image>
          <clip>
            <near>0.10000000000000001</near>
            <far>100</far>
          </clip>
        </camera>
        <always_on>true</always_on>
        <update_rate>30</update_rate>
        <visualize>true</visualize>
        <topic>camera/image_raw</topic>
        <pose>0.033169999999999998 0 0.063430200000000006 0 0.139626 0</pose>
        <gz_frame_id>front_camera_link</gz_frame_id>
      </sensor>
      <sensor name='imu' type='imu'>
        <always_on>true</always_on>
        <update_rate>100</update_rate>
        <visualize>true</visualize>
        <topic>imu_raw</topic>
        <enable_metrics>true</enable_metrics>
        <pose>-0.043999999999999997 0 0.080500000000000002 0 0 0</pose>
        <gz_frame_id>imu_link</gz_frame_id>
        <imu/>
      </sensor>
      <sensor name='gpu_lidar' type='gpu_lidar'>
        <topic>scan</topic>
        <update_rate>10</update_rate>
        <lidar>
          <scan>
            <horizontal>
              <samples>640</samples>
              <min_angle>-3.1415926535897931</min_angle>
              <max_angle>3.1415926535897931</max_angle>
              <resolution>1</resolution>
            </horizontal>
            <vertical>
              <samples>1</samples>
              <resolution>0.01</resolution>
              <min_angle>0</min_angle>
              <max_angle>0</max_angle>
            </vertical>
          </scan>
          <range>
            <min>0.050000000000000003</min>
            <max>12</max>
            <resolution>0.029999999999999999</resolution>
          </range>
          <noise>
            <type>gaussian</type>
            <mean>0</mean>
            <stddev>0.02</stddev>
          </noise>
        </lidar>
        <visualize>false</visualize>
        <pose>-0.017000000000000001 0 0.125 0 0 3.1415899999999999</pose>
        <gz_frame_id>rplidar_link</gz_frame_id>
      </sensor>
    </link>
    <joint name='caster_rotate_joint' type='revolute'>
      <pose relative_to='base_footprint'>-0.058500000000000003 0 0.017500000000000002 0 0 0</pose>
      <parent>base_footprint</parent>
      <child>caster_roate_link</child>
      <axis>
        <xyz>0 0 1</xyz>
        <limit>
          <lower>-inf</lower>
          <upper>inf</upper>
        </limit>
        <dynamics>
          <spring_reference>0</spring_reference>
          <spring_stiffness>0</spring_stiffness>
        </dynamics>
      </axis>
    </joint>
    <link name='caster_roate_link'>
      <pose relative_to='caster_rotate_joint'>0 0 0 0 0 0</pose>
      <inertial>
        <pose>-0.01 0 -0.0060000000000000001 0 0 0</pose>
        <mass>0.050000000000000003</mass>
        <inertia>
          <ixx>1.483333333333333e-06</ixx>
          <ixy>0</ixy>
          <ixz>0</ixz>
          <iyy>1.766666666666667e-06</iyy>
          <iyz>0</iyz>
          <izz>2.4166666666666671e-06</izz>
        </inertia>
      </inertial>
      <collision name='caster_roate_link_collision'>
        <pose>0 0 0 0 0 0</pose>
        <geometry>
          <mesh>
            <scale>1 1 1</scale>
            <uri>model://PinkyPro/meshes/collision/caster_rotate.stl</uri>
          </mesh>
        </geometry>
      </collision>
      <visual name='caster_roate_link_visual'>
        <pose>0 0 0 0 0 0</pose>
        <geometry>
          <mesh>
            <scale>1 1 1</scale>
            <uri>model://PinkyPro/meshes/visual/caster_rotate.dae</uri>
          </mesh>
        </geometry>
      </visual>
    </link>
    <joint name='caster_wheel_joint' type='revolute'>
      <pose relative_to='caster_roate_link'>-0.010999999999999999 0 -0.010999999999999999 0 0 0</pose>
      <parent>caster_roate_link</parent>
      <child>caster_wheel</child>
      <axis>
        <xyz>0 1 0</xyz>
        <limit>
          <lower>-inf</lower>
          <upper>inf</upper>
        </limit>
        <dynamics>
          <spring_reference>0</spring_reference>
          <spring_stiffness>0</spring_stiffness>
        </dynamics>
      </axis>
    </joint>
    <link name='caster_wheel'>
      <pose relative_to='caster_wheel_joint'>0 0 0 0 0 0</pose>
      <inertial>
        <pose>0 0 0 0 0 0</pose>
        <mass>0.050000000000000003</mass>
        <inertia>
          <ixx>8.4499999999999985e-07</ixx>
          <ixy>0</ixy>
          <ixz>0</ixz>
          <iyy>8.4499999999999985e-07</iyy>
          <iyz>0</iyz>
          <izz>8.4499999999999985e-07</izz>
        </inertia>
      </inertial>
      <collision name='caster_wheel_collision'>
        <pose>0 0 0 0 0 0</pose>
        <geometry>
          <sphere>
            <radius>0.0064999999999999997</radius>
          </sphere>
        </geometry>
        <surface>
          <contact>
            <ode>
              <kp>10000000</kp>
              <kd>1</kd>
            </ode>
          </contact>
          <friction>
            <ode>
              <mu>0.10000000000000001</mu>
              <mu2>0.10000000000000001</mu2>
            </ode>
          </friction>
        </surface>
      </collision>
      <visual name='caster_wheel_visual'>
        <pose>0 0 0 0 0 0</pose>
        <geometry>
          <mesh>
            <scale>1 1 1</scale>
            <uri>model://PinkyPro/meshes/visual/caster_wheel.dae</uri>
          </mesh>
        </geometry>
      </visual>
      <self_collide>false</self_collide>
    </link>
    <joint name='l_wheel_joint' type='revolute'>
      <pose relative_to='base_footprint'>0 0.040550000000000003 0.028000000000000001 0 0 0</pose>
      <parent>base_footprint</parent>
      <child>l_wheel</child>
      <axis>
        <xyz>0 1 0</xyz>
        <limit>
          <lower>-inf</lower>
          <upper>inf</upper>
        </limit>
        <dynamics>
          <spring_reference>0</spring_reference>
          <spring_stiffness>0</spring_stiffness>
        </dynamics>
      </axis>
    </joint>
    <link name='l_wheel'>
      <pose relative_to='l_wheel_joint'>0 0 0 0 0 0</pose>
      <inertial>
        <pose>0 0.0080000000000000002 0 0 0 0</pose>
        <mass>0.20000000000000001</mass>
        <inertia>
          <ixx>6.2720000000000009e-05</ixx>
          <ixy>0</ixy>
          <ixz>0</ixz>
          <iyy>6.2720000000000009e-05</iyy>
          <iyz>0</iyz>
          <izz>6.2720000000000009e-05</izz>
        </inertia>
      </inertial>
      <collision name='l_wheel_collision'>
        <pose>0 0.0080000000000000002 0 0 0 0</pose>
        <geometry>
          <sphere>
            <radius>0.028000000000000001</radius>
          </sphere>
        </geometry>
        <surface>
          <contact>
            <ode>
              <kp>10000000</kp>
              <kd>1</kd>
            </ode>
          </contact>
          <friction>
            <ode>
              <mu>200</mu>
              <mu2>200</mu2>
            </ode>
          </friction>
        </surface>
      </collision>
      <visual name='l_wheel_visual'>
        <pose>0 0 0 0 0 1.5707963267948959</pose>
        <geometry>
          <mesh>
            <scale>1 1 1</scale>
            <uri>model://PinkyPro/meshes/visual/main_wheel.dae</uri>
          </mesh>
        </geometry>
      </visual>
      <self_collide>false</self_collide>
    </link>
    <joint name='r_wheel_joint' type='revolute'>
      <pose relative_to='base_footprint'>0 -0.040550000000000003 0.028000000000000001 0 0 0</pose>
      <parent>base_footprint</parent>
      <child>r_wheel</child>
      <axis>
        <xyz>0 1 0</xyz>
        <limit>
          <lower>-inf</lower>
          <upper>inf</upper>
        </limit>
        <dynamics>
          <spring_reference>0</spring_reference>
          <spring_stiffness>0</spring_stiffness>
        </dynamics>
      </axis>
    </joint>
    <link name='r_wheel'>
      <pose relative_to='r_wheel_joint'>0 0 0 0 0 0</pose>
      <inertial>
        <pose>0 -0.0080000000000000002 0 0 0 0</pose>
        <mass>0.20000000000000001</mass>
        <inertia>
          <ixx>6.2720000000000009e-05</ixx>
          <ixy>0</ixy>
          <ixz>0</ixz>
          <iyy>6.2720000000000009e-05</iyy>
          <iyz>0</iyz>
          <izz>6.2720000000000009e-05</izz>
        </inertia>
      </inertial>
      <collision name='r_wheel_collision'>
        <pose>0 -0.0080000000000000002 0 0 0 0</pose>
        <geometry>
          <sphere>
            <radius>0.028000000000000001</radius>
          </sphere>
        </geometry>
        <surface>
          <contact>
            <ode>
              <kp>10000000</kp>
              <kd>1</kd>
            </ode>
          </contact>
          <friction>
            <ode>
              <mu>200</mu>
              <mu2>200</mu2>
            </ode>
          </friction>
        </surface>
      </collision>
      <visual name='r_wheel_visual'>
        <pose>0 0 0 0 0 -1.5707963267948959</pose>
        <geometry>
          <mesh>
            <scale>1 1 1</scale>
            <uri>model://PinkyPro/meshes/visual/main_wheel.dae</uri>
          </mesh>
        </geometry>
      </visual>
      <self_collide>false</self_collide>
    </link>
    <joint name='robot_lamp_mount_fixed_joint' type='revolute'>
      <pose relative_to='base_footprint'>0 0 0.028000000000000001 0 0 0</pose>
      <parent>base_footprint</parent>
      <child>robot_lamp</child>
      <axis>
        <limit>
          <lower>0</lower>
          <upper>0</upper>
        </limit>
        <dynamics>
          <damping>0</damping>
          <friction>0</friction>
          <spring_reference>0</spring_reference>
          <spring_stiffness>0</spring_stiffness>
        </dynamics>
        <xyz>0 0 1</xyz>
      </axis>
      <physics>
        <ode>
          <limit>
            <cfm>0</cfm>
            <erp>0.20000000000000001</erp>
          </limit>
        </ode>
      </physics>
    </joint>
    <link name='robot_lamp'>
      <pose relative_to='robot_lamp_mount_fixed_joint'>0 0 0 0 0 0</pose>
      <inertial>
        <pose>-0.064250000000000002 0 0.078 0 0 0</pose>
        <mass>0.01</mass>
        <inertia>
          <ixx>3.0733333333333341e-06</ixx>
          <ixy>0</ixy>
          <ixz>0</ixz>
          <iyy>4.9687500000000001e-07</iyy>
          <iyz>0</iyz>
          <izz>3.030208333333334e-06</izz>
        </inertia>
      </inertial>
      <collision name='robot_lamp_collision'>
        <pose>0 0 0 0 0 0</pose>
        <geometry>
          <mesh>
            <scale>1 1 1</scale>
            <uri>model://PinkyPro/meshes/collision/robot_lamp.stl</uri>
          </mesh>
        </geometry>
      </collision>
      <visual name='robot_lamp_visual'>
        <pose>0 0 0 0 0 0</pose>
        <geometry>
          <mesh>
            <scale>1 1 1</scale>
            <uri>model://PinkyPro/meshes/visual/robot_lamp.dae</uri>
          </mesh>
        </geometry>
      </visual>
    </link>
    <!-- RMF slotcar plugin for fleet management -->
    <plugin name="slotcar" filename="libslotcar.so">
      <!-- Drive parameters -->
      <nominal_drive_speed>0.5</nominal_drive_speed>
      <nominal_drive_acceleration>0.3</nominal_drive_acceleration>
      <max_drive_acceleration>0.5</max_drive_acceleration>

      <!-- Turn parameters -->
      <nominal_turn_speed>0.4</nominal_turn_speed>
      <nominal_turn_acceleration>0.8</nominal_turn_acceleration>
      <max_turn_acceleration>1.0</max_turn_acceleration>

      <stop_distance>0.3</stop_distance>
      <stop_radius>0.3</stop_radius>

      <!-- Can the robot drive backwards -->
      <reversible>true</reversible>

      <!-- Battery params -->
      <nominal_voltage>12.0</nominal_voltage>
      <nominal_capacity>10.0</nominal_capacity>
      <charging_current>5.0</charging_current>

      <!-- Physical params -->
      <mass>1.03</mass>
      <inertia>1.0</inertia>
      <friction_coefficient>0.22</friction_coefficient>

      <!-- Power systems -->
      <nominal_power>10.0</nominal_power>
    </plugin>
    <plugin name='gz::sim::systems::JointStatePublisher' filename='gz-sim-joint-state-publisher-system'>
      <topic>joint_states</topic>
      <joint_name>l_wheel_joint</joint_name>
      <joint_name>r_wheel_joint</joint_name>
    </plugin>
    <plugin name='pinky_gz_sim::LampControlPlugin' filename='gz-sim-lamp-control-system'>
      <link>robot_lamp</link>
    </plugin>
    <frame name='caster_mount_fixed_joint' attached_to='base_link'>
      <pose>-0.058500000000000003 0 -0.0070000000000000001 0 0 0</pose>
    </frame>
    <frame name='caster_mount_link' attached_to='caster_mount_fixed_joint'>
      <pose>0 0 0 0 0 0</pose>
    </frame>
    <frame name='front_camera_fixed_joint' attached_to='front_camera_mount'>
      <pose>0.014999999999999999 0 -0.0121 0 0 0</pose>
    </frame>
    <frame name='front_camera_link' attached_to='front_camera_fixed_joint'>
      <pose>0 0 0 0 0 0</pose>
    </frame>
    <frame name='front_camera_mount_fixed_joint' attached_to='base_link'>
      <pose>0.02 0 0.049500000000000002 0 0.13962634015954656 0</pose>
    </frame>
    <frame name='front_camera_mount' attached_to='front_camera_mount_fixed_joint'>
      <pose>0 0 0 0 0 0</pose>
    </frame>
    <frame name='imu_fixed_joint' attached_to='base_link'>
      <pose>-0.043999999999999997 0 0.052499999999999998 0 0 0</pose>
    </frame>
    <frame name='imu_link' attached_to='imu_fixed_joint'>
      <pose>0 0 0 0 0 0</pose>
    </frame>
    <frame name='ir_l_fixed_joint' attached_to='base_link'>
      <pose>0.029499999999999998 0.02 -0.014999999999999999 0 0 0</pose>
    </frame>
    <frame name='ir_l_link' attached_to='ir_l_fixed_joint'>
      <pose>0 0 0 0 0 0</pose>
    </frame>
    <frame name='ir_mid_fixed_joint' attached_to='base_link'>
      <pose>0.029499999999999998 0 -0.014999999999999999 0 0 0</pose>
    </frame>
    <frame name='ir_mid_link' attached_to='ir_mid_fixed_joint'>
      <pose>0 0 0 0 0 0</pose>
    </frame>
    <frame name='ir_r_fixed_joint' attached_to='base_link'>
      <pose>0.029499999999999998 -0.02 -0.014999999999999999 0 0 0</pose>
    </frame>
    <frame name='ir_r_link' attached_to='ir_r_fixed_joint'>
      <pose>0 0 0 0 0 0</pose>
    </frame>
    <frame name='rplidar_link_fixed_joint' attached_to='rplidar_mount'>
      <pose>0 0 0.029999999999999999 0 0 3.1415926535897931</pose>
    </frame>
    <frame name='rplidar_link' attached_to='rplidar_link_fixed_joint'>
      <pose>0 0 0 0 0 0</pose>
    </frame>
    <frame name='rplidar_mount_fixed_joint' attached_to='base_link'>
      <pose>-0.017000000000000001 0 0.067000000000000004 0 0 0</pose>
    </frame>
    <frame name='rplidar_mount' attached_to='rplidar_mount_fixed_joint'>
      <pose>0 0 0 0 0 0</pose>
    </frame>
    <frame name='screen_mount_fixed_joint' attached_to='base_link'>
      <pose>0.016500000000000001 0 0.070999999999999994 0 -0.43633231299858238 0</pose>
    </frame>
    <frame name='screen_mount' attached_to='screen_mount_fixed_joint'>
      <pose>0 0 0 0 0 0</pose>
    </frame>
    <frame name='ultrasonic_fixed_joint' attached_to='base_link'>
      <pose>0.026700000000000002 0 0.0089999999999999993 0 0 0</pose>
    </frame>
    <frame name='ultrasonic_link' attached_to='ultrasonic_fixed_joint'>
      <pose>0 0 0 0 0 0</pose>
    </frame>
    <frame name='base_link_fixed_joint' attached_to='base_footprint'>
      <pose>0 0 0.028000000000000001 0 0 0</pose>
    </frame>
    <frame name='base_link' attached_to='base_link_fixed_joint'>
      <pose>0 0 0 0 0 0</pose>
    </frame>
  </model>
</sdf>
